<mujoco model="swimmer">
  <include file="./common/visual.xml"/>
  <include file="./common/skybox.xml"/>
  <include file="./common/materials.xml"/>

  <option timestep="0.002" density="3000">
    <flag contact="disable"/>
  </option>

  <default>
    <default class="swimmer">
      <joint type="hinge" pos="0 -.05 0" axis="0 0 1" limited="true" solreflimit=".05 1" solimplimit="0 .8 .1" armature="1e-6"/>
      <default class="inertial">
        <geom type="box" size=".001 .05 .01" rgba="0 0 0 0" mass=".01"/>
      </default>
      <default class="visual">
        <geom type="capsule" size=".01" fromto="0 -.05 0 0 .05 0" material="self" mass="0"/>
      </default>
      <site size=".01" rgba="0 0 0 0"/>
    </default>
    <default class="free">
      <joint limited="false" stiffness="0" armature="0"/>
    </default>
    <motor gear="5e-4" ctrllimited="true" ctrlrange="-1 1"/>
  </default>

  <worldbody>
    <geom name="ground" type="plane" size="2 2 0.1" material="grass_mat"/>
    <body name="head" pos="0 0 .05" childclass="swimmer">
      <light name="light_1" diffuse=".8 .8 .8" pos="0 0 1.5"/>
      <geom name="head" type="ellipsoid" size=".02 .04 .017" pos="0 -.022 0" material="self" mass="0"/>
      <geom name="nose" type="sphere" pos="0 -.06 0" size=".004" material="effector" mass="0"/>
      <geom name="eyes" type="capsule" fromto="-.006 -.054 .005 .006 -.054 .005" size=".004" material="eye" mass="0"/>
      <camera name="tracking1" pos="0.0 -0.1 0.25" xyaxes="1 0 0 0 1 1" mode="trackcom" fovy="60"/>
      <camera name="tracking2" pos="-0.45 0.25 0.075" xyaxes="0 -1 0 .3 0 1" mode="trackcom" fovy="60"/>
      <camera name="eyes" pos="0 -.058 .005" xyaxes="-1 0 0 0 0 1"/>
      <joint name="rootx" class="free" type="slide" axis="1 0 0" pos="0 -.05 0"/>
      <joint name="rooty" class="free" type="slide" axis="0 1 0" pos="0 -.05 0"/>
      <joint name="rootz" class="free" type="hinge" axis="0 0 1" pos="0 -.05 0"/>
      <geom name="inertial" class="inertial"/>
      <geom name="visual" class="visual"/>
      <site name="head"/>
    <body name="segment_0" pos="0 .1 0"><geom class="visual" name="visual_0"/><geom class="inertial" name="inertial_0"/><site name="site_0"/><joint name="joint_0" range="-120.0 120.0"/><body name="segment_1" pos="0 .1 0"><geom class="visual" name="visual_1"/><geom class="inertial" name="inertial_1"/><site name="site_1"/><joint name="joint_1" range="-120.0 120.0"/></body></body></body>
    <geom name="obstacle_0" type="cylinder" mass="1" size="0.05 0.1" rgba="0 1 0 0.5" pos="1.0809073646047302 1.8485537673493737 0.05"/><geom name="obstacle_1" type="cylinder" mass="1" size="0.05 0.1" rgba="0 1 0 0.5" pos="0.8742265648271652 1.4293826787964425 0.05"/><geom name="obstacle_2" type="cylinder" mass="1" size="0.05 0.1" rgba="0 1 0 0.5" pos="0.050107682742135395 0.786696793980938 0.05"/><geom name="obstacle_3" type="cylinder" mass="1" size="0.05 0.1" rgba="0 1 0 0.5" pos="1.2130970940665686 1.1899711029545337 0.05"/><geom name="obstacle_4" type="cylinder" mass="1" size="0.05 0.1" rgba="0 1 0 0.5" pos="1.303960653886751 1.0157690863922637 0.05"/><geom name="obstacle_5" type="cylinder" mass="1" size="0.05 0.1" rgba="0 1 0 0.5" pos="-1.8369705574185615 -1.3009787285691519 0.05"/><geom name="obstacle_6" type="cylinder" mass="1" size="0.05 0.1" rgba="0 1 0 0.5" pos="-1.1430983593909692 1.709226544392786 0.05"/><geom name="obstacle_7" type="cylinder" mass="1" size="0.05 0.1" rgba="0 1 0 0.5" pos="1.2603470902114156 -0.021571800230665517 0.05"/><geom name="obstacle_8" type="cylinder" mass="1" size="0.05 0.1" rgba="0 1 0 0.5" pos="0.3997801611056046 -0.28271056297237473 0.05"/><geom name="obstacle_9" type="cylinder" mass="1" size="0.05 0.1" rgba="0 1 0 0.5" pos="1.4100315210970091 0.702527493832211 0.05"/><geom name="obstacle_10" type="cylinder" mass="1" size="0.05 0.1" rgba="0 1 0 0.5" pos="-1.302965694136779 -0.9324890188429364 0.05"/><geom name="obstacle_11" type="cylinder" mass="1" size="0.05 0.1" rgba="0 1 0 0.5" pos="-1.7315030316702313 0.5209960846414634 0.05"/><geom name="obstacle_12" type="cylinder" mass="1" size="0.05 0.1" rgba="0 1 0 0.5" pos="-1.1092934682857605 -1.484364799181853 0.05"/><geom name="obstacle_13" type="cylinder" mass="1" size="0.05 0.1" rgba="0 1 0 0.5" pos="-0.5174201291988543 0.49208477538017803 0.05"/><geom name="obstacle_14" type="cylinder" mass="1" size="0.05 0.1" rgba="0 1 0 0.5" pos="-1.3378464676565147 1.3049372953168548 0.05"/><geom name="obstacle_15" type="cylinder" mass="1" size="0.05 0.1" rgba="0 1 0 0.5" pos="1.580402953803977 -0.7955092629782192 0.05"/><geom name="obstacle_16" type="cylinder" mass="1" size="0.05 0.1" rgba="0 1 0 0.5" pos="0.039352680394846296 -1.2724666068369177 0.05"/><geom name="obstacle_17" type="cylinder" mass="1" size="0.05 0.1" rgba="0 1 0 0.5" pos="-1.7319252370461542 1.9337210625077978 0.05"/><geom name="obstacle_18" type="cylinder" mass="1" size="0.05 0.1" rgba="0 1 0 0.5" pos="1.7748545535960072 -0.49477680011727054 0.05"/><geom name="obstacle_19" type="cylinder" mass="1" size="0.05 0.1" rgba="0 1 0 0.5" pos="1.9837025107848971 -1.4632592998290486 0.05"/><geom name="obstacle_20" type="cylinder" mass="1" size="0.05 0.1" rgba="0 1 0 0.5" pos="-1.5874759126324278 -1.5580100173440923 0.05"/><geom name="obstacle_21" type="cylinder" mass="1" size="0.05 0.1" rgba="0 1 0 0.5" pos="-1.6109351242742231 0.10987675962631371 0.05"/><geom name="obstacle_22" type="cylinder" mass="1" size="0.05 0.1" rgba="0 1 0 0.5" pos="-1.492446607994221 -0.6714292790133456 0.05"/><geom name="obstacle_23" type="cylinder" mass="1" size="0.05 0.1" rgba="0 1 0 0.5" pos="-0.9611702456888214 1.2472777220364324 0.05"/><geom name="obstacle_24" type="cylinder" mass="1" size="0.05 0.1" rgba="0 1 0 0.5" pos="-1.7309108144761738 1.7342502986460975 0.05"/><geom name="obstacle_25" type="cylinder" mass="1" size="0.05 0.1" rgba="0 1 0 0.5" pos="1.570445799966885 -1.857946323082666 0.05"/><geom name="obstacle_26" type="cylinder" mass="1" size="0.05 0.1" rgba="0 1 0 0.5" pos="-1.501714615764337 0.9315171895388903 0.05"/><geom name="obstacle_27" type="cylinder" mass="1" size="0.05 0.1" rgba="0 1 0 0.5" pos="1.6814676780478655 1.3736797497479025 0.05"/><geom name="obstacle_28" type="cylinder" mass="1" size="0.05 0.1" rgba="0 1 0 0.5" pos="-0.23823313442823268 -0.804628585785073 0.05"/><geom name="obstacle_29" type="cylinder" mass="1" size="0.05 0.1" rgba="0 1 0 0.5" pos="-0.9139376072850958 -0.236953596417111 0.05"/><geom name="obstacle_30" type="cylinder" mass="1" size="0.05 0.1" rgba="0 1 0 0.5" pos="0.13296471264011478 -1.1788711807756758 0.05"/><geom name="obstacle_31" type="cylinder" mass="1" size="0.05 0.1" rgba="0 1 0 0.5" pos="1.0200410699217572 -0.44282865283556294 0.05"/><geom name="obstacle_32" type="cylinder" mass="1" size="0.05 0.1" rgba="0 1 0 0.5" pos="-0.8193321042730521 1.2796223748846387 0.05"/><geom name="obstacle_33" type="cylinder" mass="1" size="0.05 0.1" rgba="0 1 0 0.5" pos="-1.6438139497984041 -1.4572620420080997 0.05"/><geom name="obstacle_34" type="cylinder" mass="1" size="0.05 0.1" rgba="0 1 0 0.5" pos="1.7944946668552908 0.8857538362039725 0.05"/><geom name="obstacle_35" type="cylinder" mass="1" size="0.05 0.1" rgba="0 1 0 0.5" pos="0.7941806174453103 1.1482302043753845 0.05"/><geom name="obstacle_36" type="cylinder" mass="1" size="0.05 0.1" rgba="0 1 0 0.5" pos="1.9609505216214052 0.6266940649067307 0.05"/><geom name="obstacle_37" type="cylinder" mass="1" size="0.05 0.1" rgba="0 1 0 0.5" pos="-1.8230502879400707 0.27856921797712575 0.05"/><geom name="obstacle_38" type="cylinder" mass="1" size="0.05 0.1" rgba="0 1 0 0.5" pos="0.39693300522294983 0.8175009980958401 0.05"/><geom name="obstacle_39" type="cylinder" mass="1" size="0.05 0.1" rgba="0 1 0 0.5" pos="-0.033524926835627245 -0.5300939039011379 0.05"/><geom name="obstacle_40" type="cylinder" mass="1" size="0.05 0.1" rgba="0 1 0 0.5" pos="-0.7876107462356106 -1.694838027310694 0.05"/><geom name="obstacle_41" type="cylinder" mass="1" size="0.05 0.1" rgba="0 1 0 0.5" pos="0.06820573599317958 -1.0488372894947275 0.05"/><geom name="obstacle_42" type="cylinder" mass="1" size="0.05 0.1" rgba="0 1 0 0.5" pos="-1.4711988734790258 0.3505216059679044 0.05"/><geom name="obstacle_43" type="cylinder" mass="1" size="0.05 0.1" rgba="0 1 0 0.5" pos="1.853714869353373 1.7082067902788274 0.05"/><geom name="obstacle_44" type="cylinder" mass="1" size="0.05 0.1" rgba="0 1 0 0.5" pos="1.4025990372403208 -0.18580647864573008 0.05"/><geom name="obstacle_45" type="cylinder" mass="1" size="0.05 0.1" rgba="0 1 0 0.5" pos="0.3972625634195528 -0.9475245369648118 0.05"/><geom name="obstacle_46" type="cylinder" mass="1" size="0.05 0.1" rgba="0 1 0 0.5" pos="1.6481704144786424 -1.5612071558657608 0.05"/><geom name="obstacle_47" type="cylinder" mass="1" size="0.05 0.1" rgba="0 1 0 0.5" pos="1.1739675360990027 -0.259193007185186 0.05"/><geom name="obstacle_48" type="cylinder" mass="1" size="0.05 0.1" rgba="0 1 0 0.5" pos="0.574168061884635 -0.9919784867488057 0.05"/><geom name="obstacle_49" type="cylinder" mass="1" size="0.05 0.1" rgba="0 1 0 0.5" pos="-1.9489370684562037 1.6968690577536183 0.05"/><geom name="obstacle_50" type="cylinder" mass="1" size="0.05 0.1" rgba="0 1 0 0.5" pos="1.1614935153815047 -0.812118087117168 0.05"/><geom name="obstacle_51" type="cylinder" mass="1" size="0.05 0.1" rgba="0 1 0 0.5" pos="1.419571378234028 1.5390857001701455 0.05"/><geom name="obstacle_52" type="cylinder" mass="1" size="0.05 0.1" rgba="0 1 0 0.5" pos="-1.2761071817743481 0.19695309321173848 0.05"/><geom name="obstacle_53" type="cylinder" mass="1" size="0.05 0.1" rgba="0 1 0 0.5" pos="-1.8157646057515548 0.18648500234867615 0.05"/><geom name="obstacle_54" type="cylinder" mass="1" size="0.05 0.1" rgba="0 1 0 0.5" pos="-0.15668994235106037 -1.833144123266901 0.05"/><geom name="obstacle_55" type="cylinder" mass="1" size="0.05 0.1" rgba="0 1 0 0.5" pos="0.819258027995641 1.3955331211670452 0.05"/><geom name="obstacle_56" type="cylinder" mass="1" size="0.05 0.1" rgba="0 1 0 0.5" pos="0.5873719193431923 1.4793456504991975 0.05"/><geom name="obstacle_57" type="cylinder" mass="1" size="0.05 0.1" rgba="0 1 0 0.5" pos="1.6940325218639107 -0.5794909794902345 0.05"/><geom name="obstacle_58" type="cylinder" mass="1" size="0.05 0.1" rgba="0 1 0 0.5" pos="-0.5119305718955016 0.7299130037407422 0.05"/><geom name="obstacle_59" type="cylinder" mass="1" size="0.05 0.1" rgba="0 1 0 0.5" pos="0.9965455446789786 -1.0320410707036243 0.05"/><geom name="obstacle_60" type="cylinder" mass="1" size="0.05 0.1" rgba="0 1 0 0.5" pos="0.07124882983160408 0.4929648140582681 0.05"/></worldbody>

  <sensor>
    <framepos name="nose_pos" objtype="geom" objname="nose"/>
    <framexaxis name="head_xaxis" objtype="xbody" objname="head"/>
    <frameyaxis name="head_yaxis" objtype="xbody" objname="head"/>
    <velocimeter name="head_vel" site="head"/>
    <gyro name="head_gyro" site="head"/>
  </sensor>

<actuator><motor name="motor_0" joint="joint_0"/><motor name="motor_1" joint="joint_1"/></actuator><sensor><velocimeter name="velocimeter_0" site="site_0"/><gyro name="gyro_0" site="site_0"/><velocimeter name="velocimeter_1" site="site_1"/><gyro name="gyro_1" site="site_1"/></sensor><asset><texture name="grass_tex" type="2d" file="../mujoco_bodies/common/OutdoorGrassFloorD.png"/><material name="grass_mat" texture="grass_tex" specular="0.3" shininess="0.1"/></asset></mujoco>
